<?xml version="1.0"?>
<robot name="TiagoBase" xmlns:xacro="http://ros.org/wiki/xacro">
  <material name="white">
     <color rgba="0.98 0.98 0.98 1"/>
  </material>

  <material name="orange">
     <color rgba="0.85 0.57 0.08 1"/>
  </material>

  <material name="black">
     <color rgba="0.1 0.1 0.1 1"/>
  </material>

  <link name="base_link">
    <visual>
      <origin xyz="0 0 0.06" rpy="0 0 0"/>
      <geometry>
        <cylinder radius="0.265" length="0.276"/>
      </geometry>
      <material name="white"/>
    </visual>
    <collision>
      <origin xyz="0 0 0.06" rpy="0 0 0"/>
      <geometry>
        <cylinder radius="0.265" length="0.276"/>
      </geometry>
    </collision>
    <visual>
      <origin xyz="-0.201 0.1062 0.28" rpy="0 0 0"/>
      <geometry>
        <cylinder radius="0.007" length="0.173"/>
      </geometry>
    </visual>
    <collision>
      <origin xyz="-0.201 0.1062 0.28" rpy="0 0 0"/>
      <geometry>
        <cylinder radius="0.007" length="0.173"/>
      </geometry>
    </collision>
    <visual>
      <origin xyz="-0.201 -0.1062 0.28" rpy="0 0 0"/>
      <geometry>
        <cylinder radius="0.007" length="0.173"/>
      </geometry>
    </visual>
    <collision>
      <origin xyz="-0.201 -0.1062 0.28" rpy="0 0 0"/>
      <geometry>
        <cylinder radius="0.007" length="0.173"/>
      </geometry>
    </collision>
  </link>
  <joint name="CASTER_WHEEL_BACK_LEFT_JOINT" type="continuous">
    <parent link="base_link"/>
    <child link="caster_back_left_1_link"/>
    <axis xyz="0 0 1"/>
    <origin xyz="-0.1735 0.102 -0.0335" rpy="0 0 -0.000001"/>
  </joint>
  <link name="caster_back_left_1_link">
    <visual>
      <origin xyz="-0.003 0 -0.022" rpy="0 0 0"/>
      <geometry>
        <box size="0.036 0.032 0.04"/>
      </geometry>
    </visual>
    <collision>
      <origin xyz="-0.003 0 -0.022" rpy="0 0 0"/>
      <geometry>
        <box size="0.036 0.032 0.04"/>
      </geometry>
    </collision>
  </link>
  <joint name="SMALL_WHEEL_JOINT" type="continuous">
    <parent link="caster_back_left_1_link"/>
    <child link="caster_back_left_2_link"/>
    <axis xyz="0 -0.000004 1"/>
    <origin xyz="-0.016 0 -0.04" rpy="-1.5708 0.000043 0"/>
  </joint>
  <link name="caster_back_left_2_link">
    <visual>
      <origin xyz="0 0 0" rpy="0 0 0"/>
      <geometry>
        <cylinder radius="0.025" length="0.015"/>
      </geometry>
    </visual>
    <collision>
      <origin xyz="0 0 0" rpy="0 0 0"/>
      <geometry>
        <cylinder radius="0.025" length="0.015"/>
      </geometry>
    </collision>
  </link>
  <joint name="CASTER_WHEEL_BACK_RIGHT_JOINT" type="continuous">
    <parent link="base_link"/>
    <child link="caster_back_right_1_link"/>
    <axis xyz="0 0 1"/>
    <origin xyz="-0.1735 -0.102 -0.0335" rpy="0 0 -0.000001"/>
  </joint>
  <link name="caster_back_right_1_link">
    <visual>
      <origin xyz="-0.003 0 -0.022" rpy="0 0 0"/>
      <geometry>
        <box size="0.036 0.032 0.04"/>
      </geometry>
    </visual>
    <collision>
      <origin xyz="-0.003 0 -0.022" rpy="0 0 0"/>
      <geometry>
        <box size="0.036 0.032 0.04"/>
      </geometry>
    </collision>
  </link>
  <joint name="SMALL_WHEEL_JOINT_0" type="continuous">
    <parent link="caster_back_right_1_link"/>
    <child link="caster_back_right_2_link"/>
    <axis xyz="0 -0.000004 1"/>
    <origin xyz="-0.016 0 -0.04" rpy="-1.5708 0.000043 0"/>
  </joint>
  <link name="caster_back_right_2_link">
    <visual>
      <origin xyz="0 0 0" rpy="0 0 0"/>
      <geometry>
        <cylinder radius="0.025" length="0.015"/>
      </geometry>
    </visual>
    <collision>
      <origin xyz="0 0 0" rpy="0 0 0"/>
      <geometry>
        <cylinder radius="0.025" length="0.015"/>
      </geometry>
    </collision>
  </link>
  <joint name="CASTER_WHEEL_FRONT_LEFT_JOINT" type="continuous">
    <parent link="base_link"/>
    <child link="caster_front_left_1_link"/>
    <axis xyz="0 0 1"/>
    <origin xyz="0.1695 0.102 -0.0335" rpy="0 0 -0.000001"/>
  </joint>
  <link name="caster_front_left_1_link">
    <visual>
      <origin xyz="-0.003 0 -0.022" rpy="0 0 0"/>
      <geometry>
        <box size="0.036 0.032 0.04"/>
      </geometry>
    </visual>
    <collision>
      <origin xyz="-0.003 0 -0.022" rpy="0 0 0"/>
      <geometry>
        <box size="0.036 0.032 0.04"/>
      </geometry>
    </collision>
  </link>
  <joint name="SMALL_WHEEL_JOINT_1" type="continuous">
    <parent link="caster_front_left_1_link"/>
    <child link="caster_front_left_2_link"/>
    <axis xyz="0 -0.000004 1"/>
    <origin xyz="-0.016 0 -0.04" rpy="-1.5708 -0.000015 0"/>
  </joint>
  <link name="caster_front_left_2_link">
    <visual>
      <origin xyz="0 0 0" rpy="0 0 0"/>
      <geometry>
        <cylinder radius="0.025" length="0.015"/>
      </geometry>
    </visual>
    <collision>
      <origin xyz="0 0 0" rpy="0 0 0"/>
      <geometry>
        <cylinder radius="0.025" length="0.015"/>
      </geometry>
    </collision>
  </link>
  <joint name="CASTER_WHEEL_FRONT_RIGHT_JOINT" type="continuous">
    <parent link="base_link"/>
    <child link="caster_front_right_1_link"/>
    <axis xyz="0 0 1"/>
    <origin xyz="0.1695 -0.102 -0.0335" rpy="0 0 -0.000001"/>
  </joint>
  <link name="caster_front_right_1_link">
    <visual>
      <origin xyz="-0.003 0 -0.022" rpy="0 0 0"/>
      <geometry>
        <box size="0.036 0.032 0.04"/>
      </geometry>
    </visual>
    <collision>
      <origin xyz="-0.003 0 -0.022" rpy="0 0 0"/>
      <geometry>
        <box size="0.036 0.032 0.04"/>
      </geometry>
    </collision>
  </link>
  <joint name="SMALL_WHEEL_JOINT_2" type="continuous">
    <parent link="caster_front_right_1_link"/>
    <child link="caster_front_right_2_link"/>
    <axis xyz="0 -0.000004 1"/>
    <origin xyz="-0.016 0 -0.04" rpy="-1.5708 -0.000015 0"/>
  </joint>
  <link name="caster_front_right_2_link">
    <visual>
      <origin xyz="0 0 0" rpy="0 0 0"/>
      <geometry>
        <cylinder radius="0.025" length="0.015"/>
      </geometry>
    </visual>
    <collision>
      <origin xyz="0 0 0" rpy="0 0 0"/>
      <geometry>
        <cylinder radius="0.025" length="0.015"/>
      </geometry>
    </collision>
  </link>
  <joint name="wheel_left_joint" type="continuous">
    <parent link="base_link"/>
    <child link="wheel_left_link"/>
    <axis xyz="0 -0.000004 -1"/>
    <limit effort="10" velocity="10.1523"/>
    <origin xyz="0 0.2022 0" rpy="1.5708 0 0"/>
  </joint>
  <link name="wheel_left_link">
    <visual>
      <origin xyz="0 0 0.0002" rpy="0 0 0"/>
      <geometry>
        <cylinder radius="0.0985" length="0.04"/>
      </geometry>
      <material name="black"/>
    </visual>
    <collision>
      <origin xyz="0 0 0.0002" rpy="0 0 0"/>
      <geometry>
        <cylinder radius="0.0985" length="0.04"/>
      </geometry>
    </collision>
  </link>
  <joint name="wheel_right_joint" type="continuous">
    <parent link="base_link"/>
    <child link="wheel_right_link"/>
    <axis xyz="0 -0.000004 -1"/>
    <limit effort="10" velocity="10.1523"/>
    <origin xyz="0 -0.2022 0.0002" rpy="1.5708 0 0"/>
  </joint>
  <link name="wheel_right_link">
    <visual>
      <origin xyz="0 0 -0.0002" rpy="0 0 0"/>
      <geometry>
        <cylinder radius="0.0985" length="0.04"/>
      </geometry>
      <material name="black"/>
    </visual>
    <collision>
      <origin xyz="0 0 -0.0002" rpy="0 0 0"/>
      <geometry>
        <cylinder radius="0.0985" length="0.04"/>
      </geometry>
    </collision>
  </link>
  <link name="base_sonar_01_link">
  </link>
  <joint name="base_link_base_sonar_01_link_joint" type="fixed">
    <parent link="base_link"/>
    <child link="base_sonar_01_link"/>
    <origin xyz="-0.183 -0.183 0.1728" rpy="0 0 -2.356185"/>
  </joint>
  <link name="base_sonar_02_link">
  </link>
  <joint name="base_link_base_sonar_02_link_joint" type="fixed">
    <parent link="base_link"/>
    <child link="base_sonar_02_link"/>
    <origin xyz="-0.259 0 0.173" rpy="0 0 -3.141585"/>
  </joint>
  <link name="base_sonar_03_link">
  </link>
  <joint name="base_link_base_sonar_03_link_joint" type="fixed">
    <parent link="base_link"/>
    <child link="base_sonar_03_link"/>
    <origin xyz="-0.183 0.183 0.173" rpy="0 0 2.3562"/>
  </joint>
  <link name="base_cover_link">
    <visual>
      <origin xyz="0 0 0.043" rpy="0 0 0"/>
      <geometry>
        <cylinder radius="0.272" length="0.086"/>
      </geometry>
      <material name="orange"/>
    </visual>
    <collision>
      <origin xyz="0 0 0.043" rpy="0 0 0"/>
      <geometry>
        <cylinder radius="0.272" length="0.086"/>
      </geometry>
    </collision>
  </link>
  <joint name="base_link_base_cover_link_joint" type="fixed">
    <parent link="base_link"/>
    <child link="base_cover_link"/>
    <origin xyz="0 0 0.029996" rpy="0 0 0"/>
  </joint>
  <link name="base_footprint">
  </link>
  <joint name="base_link_base_footprint_joint" type="fixed">
    <parent link="base_link"/>
    <child link="base_footprint"/>
    <origin xyz="0 0 -0.095" rpy="0 0 0"/>
  </joint>
  <link name="gyro">
  </link>
  <joint name="base_link_gyro_joint" type="fixed">
    <parent link="base_link"/>
    <child link="gyro"/>
    <origin xyz="0 0 0" rpy="0 0 0"/>
  </joint>
  <link name="inertial unit">
  </link>
  <joint name="base_link_inertial unit_joint" type="fixed">
    <parent link="base_link"/>
    <child link="inertial unit"/>
    <origin xyz="0 0 0" rpy="0 0 0"/>
  </joint>
  <link name="accelerometer">
  </link>
  <joint name="base_link_accelerometer_joint" type="fixed">
    <parent link="base_link"/>
    <child link="accelerometer"/>
    <origin xyz="0 0 0" rpy="0 0 0"/>
  </joint>
  <link name="Hokuyo_URG_04LX_UG01">
    <visual>
      <origin xyz="0 0 -0.018" rpy="1.570741 0.000118 -1.570741"/>
      <geometry>
        <box size="0.05 0.07 0.05"/>
      </geometry>
    </visual>
    <collision>
      <origin xyz="0 0 -0.018" rpy="1.570741 0.000118 -1.570741"/>
      <geometry>
        <box size="0.05 0.07 0.05"/>
      </geometry>
    </collision>
  </link>
  <joint name="base_link_Hokuyo_URG_04LX_UG01_joint" type="fixed">
    <parent link="base_link"/>
    <child link="Hokuyo_URG_04LX_UG01"/>
    <origin xyz="0.202 0 -0.004" rpy="0 0 0"/>
  </joint>
</robot>
